Workbook

Sheet Grupos
A1: QUINIELA MUNDIAL 2026 — FASE DE GRUPOS (llena SOLO las columnas D y E)
A2: Posiciones AUTO-CALCULADAS: pts → dif → GF → alfabético. NO editar columnas H-Q. Template reconstruido 11-jun-2026 (ver data/estructura_torneo.md).
A4: GRUPO A
A5: # | B5: Fecha | C5: Local | D5: GL | E5: GV | F5: Visitante | H5: Equipo | I5: PJ | J5: Pts | K5: GF | L5: GC | M5: Dif | N5: Score | O5: Pos
A6: 1 | B6: 2026-06-11 | C6: México | D6: 2 | E6: 0 | F6: Sudáfrica | H6: México | I6: =SUMPRODUCT(($C$6:$C$11=$H6)*($D$6:$D$11<>"")*($E$6:$E$11<>""))+SUMPRODUCT(($F$6:$F$11=$H6)*($D$6:$D$11<>"")*($E$6:$E$11<>"")) -> 3 | J6: =SUMPRODUCT(($C$6:$C$11=$H6)*($D$6:$D$11<>"")*($E$6:$E$11<>"")*($D$6:$D$11>$E$6:$E$11))*3+SUMPRODUCT(($F$6:$F$11=$H6)*($D$6:$D$11<>"")*($E$6:$E$11<>"")*($E$6:$E$11>$D$6:$D$11))*3+SUMPRODUCT((($C$6:$C$11=$H6)+($F$6:$F$11=$H6))*($D$6:$D$11<>"")*($E$6:$E$11<>"")*($D$6:$D$11=$E$6:$E$11)) -> 9 | K6: =SUMPRODUCT(($C$6:$C$11=$H6)*($D$6:$D$11<>"")*($E$6:$E$11<>"")*$D$6:$D$11)+SUMPRODUCT(($F$6:$F$11=$H6)*($D$6:$D$11<>"")*($E$6:$E$11<>"")*$E$6:$E$11) -> 5 | L6: =SUMPRODUCT(($C$6:$C$11=$H6)*($D$6:$D$11<>"")*($E$6:$E$11<>"")*$E$6:$E$11)+SUMPRODUCT(($F$6:$F$11=$H6)*($D$6:$D$11<>"")*($E$6:$E$11<>"")*$D$6:$D$11) -> 0 | M6: =K6-L6 -> 5 | N6: =J6*10000000+(M6+100)*10000+K6*10+(3-COUNTIF($H$6:$H$11,"<"&H6)) -> 91050051 | O6: =RANK(N6,$N$6:$N$11) -> 1 | Q6: 1°: | R6: =INDEX($H$6:$H$11,MATCH(1,$O$6:$O$11,0)) -> México
A7: 2 | B7: 2026-06-11 | C7: Corea del Sur | D7: 1 | E7: 1 | F7: Chequia | H7: Sudáfrica | I7: =SUMPRODUCT(($C$6:$C$11=$H7)*($D$6:$D$11<>"")*($E$6:$E$11<>""))+SUMPRODUCT(($F$6:$F$11=$H7)*($D$6:$D$11<>"")*($E$6:$E$11<>"")) -> 3 | J7: =SUMPRODUCT(($C$6:$C$11=$H7)*($D$6:$D$11<>"")*($E$6:$E$11<>"")*($D$6:$D$11>$E$6:$E$11))*3+SUMPRODUCT(($F$6:$F$11=$H7)*($D$6:$D$11<>"")*($E$6:$E$11<>"")*($E$6:$E$11>$D$6:$D$11))*3+SUMPRODUCT((($C$6:$C$11=$H7)+($F$6:$F$11=$H7))*($D$6:$D$11<>"")*($E$6:$E$11<>"")*($D$6:$D$11=$E$6:$E$11)) -> 1 | K7: =SUMPRODUCT(($C$6:$C$11=$H7)*($D$6:$D$11<>"")*($E$6:$E$11<>"")*$D$6:$D$11)+SUMPRODUCT(($F$6:$F$11=$H7)*($D$6:$D$11<>"")*($E$6:$E$11<>"")*$E$6:$E$11) -> 1 | L7: =SUMPRODUCT(($C$6:$C$11=$H7)*($D$6:$D$11<>"")*($E$6:$E$11<>"")*$E$6:$E$11)+SUMPRODUCT(($F$6:$F$11=$H7)*($D$6:$D$11<>"")*($E$6:$E$11<>"")*$D$6:$D$11) -> 4 | M7: =K7-L7 -> -3 | N7: =J7*10000000+(M7+100)*10000+K7*10+(3-COUNTIF($H$6:$H$11,"<"&H7)) -> 10970010 | O7: =RANK(N7,$N$6:$N$11) -> 4 | Q7: 2°: | R7: =INDEX($H$6:$H$11,MATCH(2,$O$6:$O$11,0)) -> Corea del Sur
A8: 25 | B8: 2026-06-18 | C8: Chequia | D8: 1 | E8: 1 | F8: Sudáfrica | H8: Corea del Sur | I8: =SUMPRODUCT(($C$6:$C$11=$H8)*($D$6:$D$11<>"")*($E$6:$E$11<>""))+SUMPRODUCT(($F$6:$F$11=$H8)*($D$6:$D$11<>"")*($E$6:$E$11<>"")) -> 3 | J8: =SUMPRODUCT(($C$6:$C$11=$H8)*($D$6:$D$11<>"")*($E$6:$E$11<>"")*($D$6:$D$11>$E$6:$E$11))*3+SUMPRODUCT(($F$6:$F$11=$H8)*($D$6:$D$11<>"")*($E$6:$E$11<>"")*($E$6:$E$11>$D$6:$D$11))*3+SUMPRODUCT((($C$6:$C$11=$H8)+($F$6:$F$11=$H8))*($D$6:$D$11<>"")*($E$6:$E$11<>"")*($D$6:$D$11=$E$6:$E$11)) -> 4 | K8: =SUMPRODUCT(($C$6:$C$11=$H8)*($D$6:$D$11<>"")*($E$6:$E$11<>"")*$D$6:$D$11)+SUMPRODUCT(($F$6:$F$11=$H8)*($D$6:$D$11<>"")*($E$6:$E$11<>"")*$E$6:$E$11) -> 2 | L8: =SUMPRODUCT(($C$6:$C$11=$H8)*($D$6:$D$11<>"")*($E$6:$E$11<>"")*$E$6:$E$11)+SUMPRODUCT(($F$6:$F$11=$H8)*($D$6:$D$11<>"")*($E$6:$E$11<>"")*$D$6:$D$11) -> 2 | M8: =K8-L8 -> 0 | N8: =J8*10000000+(M8+100)*10000+K8*10+(3-COUNTIF($H$6:$H$11,"<"&H8)) -> 41000022 | O8: =RANK(N8,$N$6:$N$11) -> 2 | Q8: 3°: | R8: =INDEX($H$6:$H$11,MATCH(3,$O$6:$O$11,0)) -> Chequia
A9: 26 | B9: 2026-06-18 | C9: México | D9: 1 | E9: 0 | F9: Corea del Sur | H9: Chequia | I9: =SUMPRODUCT(($C$6:$C$11=$H9)*($D$6:$D$11<>"")*($E$6:$E$11<>""))+SUMPRODUCT(($F$6:$F$11=$H9)*($D$6:$D$11<>"")*($E$6:$E$11<>"")) -> 3 | J9: =SUMPRODUCT(($C$6:$C$11=$H9)*($D$6:$D$11<>"")*($E$6:$E$11<>"")*($D$6:$D$11>$E$6:$E$11))*3+SUMPRODUCT(($F$6:$F$11=$H9)*($D$6:$D$11<>"")*($E$6:$E$11<>"")*($E$6:$E$11>$D$6:$D$11))*3+SUMPRODUCT((($C$6:$C$11=$H9)+($F$6:$F$11=$H9))*($D$6:$D$11<>"")*($E$6:$E$11<>"")*($D$6:$D$11=$E$6:$E$11)) -> 2 | K9: =SUMPRODUCT(($C$6:$C$11=$H9)*($D$6:$D$11<>"")*($E$6:$E$11<>"")*$D$6:$D$11)+SUMPRODUCT(($F$6:$F$11=$H9)*($D$6:$D$11<>"")*($E$6:$E$11<>"")*$E$6:$E$11) -> 2 | L9: =SUMPRODUCT(($C$6:$C$11=$H9)*($D$6:$D$11<>"")*($E$6:$E$11<>"")*$E$6:$E$11)+SUMPRODUCT(($F$6:$F$11=$H9)*($D$6:$D$11<>"")*($E$6:$E$11<>"")*$D$6:$D$11) -> 4 | M9: =K9-L9 -> -2 | N9: =J9*10000000+(M9+100)*10000+K9*10+(3-COUNTIF($H$6:$H$11,"<"&H9)) -> 20980023 | O9: =RANK(N9,$N$6:$N$11) -> 3
A10: 49 | B10: 2026-06-24 | C10: Chequia | D10: 0 | E10: 2 | F10: México
A11: 50 | B11: 2026-06-24 | C11: Sudáfrica | D11: 0 | E11: 1 | F11: Corea del Sur
A13: GRUPO B
A14: # | B14: Fecha | C14: Local | D14: GL | E14: GV | F14: Visitante | H14: Equipo | I14: PJ | J14: Pts | K14: GF | L14: GC | M14: Dif | N14: Score | O14: Pos
A15: 3 | B15: 2026-06-12 | C15: Canadá | D15: 1 | E15: 0 | F15: Bosnia y Herzegovina | H15: Canadá | I15: =SUMPRODUCT(($C$15:$C$20=$H15)*($D$15:$D$20<>"")*($E$15:$E$20<>""))+SUMPRODUCT(($F$15:$F$20=$H15)*($D$15:$D$20<>"")*($E$15:$E$20<>"")) -> 3 | J15: =SUMPRODUCT(($C$15:$C$20=$H15)*($D$15:$D$20<>"")*($E$15:$E$20<>"")*($D$15:$D$20>$E$15:$E$20))*3+SUMPRODUCT(($F$15:$F$20=$H15)*($D$15:$D$20<>"")*($E$15:$E$20<>"")*($E$15:$E$20>$D$15:$D$20))*3+SUMPRODUCT((($C$15:$C$20=$H15)+($F$15:$F$20=$H15))*($D$15:$D$20<>"")*($E$15:$E$20<>"")*($D$15:$D$20=$E$15:$E$20)) -> 7 | K15: =SUMPRODUCT(($C$15:$C$20=$H15)*($D$15:$D$20<>"")*($E$15:$E$20<>"")*$D$15:$D$20)+SUMPRODUCT(($F$15:$F$20=$H15)*($D$15:$D$20<>"")*($E$15:$E$20<>"")*$E$15:$E$20) -> 3 | L15: =SUMPRODUCT(($C$15:$C$20=$H15)*($D$15:$D$20<>"")*($E$15:$E$20<>"")*$E$15:$E$20)+SUMPRODUCT(($F$15:$F$20=$H15)*($D$15:$D$20<>"")*($E$15:$E$20<>"")*$D$15:$D$20) -> 1 | M15: =K15-L15 -> 2 | N15: =J15*10000000+(M15+100)*10000+K15*10+(3-COUNTIF($H$15:$H$20,"<"&H15)) -> 71020032 | O15: =RANK(N15,$N$15:$N$20) -> 1 | Q15: 1°: | R15: =INDEX($H$15:$H$20,MATCH(1,$O$15:$O$20,0)) -> Canadá
A16: 5 | B16: 2026-06-13 | C16: Catar | D16: 0 | E16: 1 | F16: Suiza | H16: Bosnia y Herzegovina | I16: =SUMPRODUCT(($C$15:$C$20=$H16)*($D$15:$D$20<>"")*($E$15:$E$20<>""))+SUMPRODUCT(($F$15:$F$20=$H16)*($D$15:$D$20<>"")*($E$15:$E$20<>"")) -> 3 | J16: =SUMPRODUCT(($C$15:$C$20=$H16)*($D$15:$D$20<>"")*($E$15:$E$20<>"")*($D$15:$D$20>$E$15:$E$20))*3+SUMPRODUCT(($F$15:$F$20=$H16)*($D$15:$D$20<>"")*($E$15:$E$20<>"")*($E$15:$E$20>$D$15:$D$20))*3+SUMPRODUCT((($C$15:$C$20=$H16)+($F$15:$F$20=$H16))*($D$15:$D$20<>"")*($E$15:$E$20<>"")*($D$15:$D$20=$E$15:$E$20)) -> 1 | K16: =SUMPRODUCT(($C$15:$C$20=$H16)*($D$15:$D$20<>"")*($E$15:$E$20<>"")*$D$15:$D$20)+SUMPRODUCT(($F$15:$F$20=$H16)*($D$15:$D$20<>"")*($E$15:$E$20<>"")*$E$15:$E$20) -> 1 | L16: =SUMPRODUCT(($C$15:$C$20=$H16)*($D$15:$D$20<>"")*($E$15:$E$20<>"")*$E$15:$E$20)+SUMPRODUCT(($F$15:$F$20=$H16)*($D$15:$D$20<>"")*($E$15:$E$20<>"")*$D$15:$D$20) -> 3 | M16: =K16-L16 -> -2 | N16: =J16*10000000+(M16+100)*10000+K16*10+(3-COUNTIF($H$15:$H$20,"<"&H16)) -> 10980013 | O16: =RANK(N16,$N$15:$N$20) -> 3 | Q16: 2°: | R16: =INDEX($H$15:$H$20,MATCH(2,$O$15:$O$20,0)) -> Suiza
A17: 27 | B17: 2026-06-18 | C17: Suiza | D17: 1 | E17: 0 | F17: Bosnia y Herzegovina | H17: Catar | I17: =SUMPRODUCT(($C$15:$C$20=$H17)*($D$15:$D$20<>"")*($E$15:$E$20<>""))+SUMPRODUCT(($F$15:$F$20=$H17)*($D$15:$D$20<>"")*($E$15:$E$20<>"")) -> 3 | J17: =SUMPRODUCT(($C$15:$C$20=$H17)*($D$15:$D$20<>"")*($E$15:$E$20<>"")*($D$15:$D$20>$E$15:$E$20))*3+SUMPRODUCT(($F$15:$F$20=$H17)*($D$15:$D$20<>"")*($E$15:$E$20<>"")*($E$15:$E$20>$D$15:$D$20))*3+SUMPRODUCT((($C$15:$C$20=$H17)+($F$15:$F$20=$H17))*($D$15:$D$20<>"")*($E$15:$E$20<>"")*($D$15:$D$20=$E$15:$E$20)) -> 1 | K17: =SUMPRODUCT(($C$15:$C$20=$H17)*($D$15:$D$20<>"")*($E$15:$E$20<>"")*$D$15:$D$20)+SUMPRODUCT(($F$15:$F$20=$H17)*($D$15:$D$20<>"")*($E$15:$E$20<>"")*$E$15:$E$20) -> 1 | L17: =SUMPRODUCT(($C$15:$C$20=$H17)*($D$15:$D$20<>"")*($E$15:$E$20<>"")*$E$15:$E$20)+SUMPRODUCT(($F$15:$F$20=$H17)*($D$15:$D$20<>"")*($E$15:$E$20<>"")*$D$15:$D$20) -> 3 | M17: =K17-L17 -> -2 | N17: =J17*10000000+(M17+100)*10000+K17*10+(3-COUNTIF($H$15:$H$20,"<"&H17)) -> 10980011 | O17: =RANK(N17,$N$15:$N$20) -> 4 | Q17: 3°: | R17: =INDEX($H$15:$H$20,MATCH(3,$O$15:$O$20,0)) -> Bosnia y Herzegovina
A18: 28 | B18: 2026-06-18 | C18: Canadá | D18: 1 | E18: 0 | F18: Catar | H18: Suiza | I18: =SUMPRODUCT(($C$15:$C$20=$H18)*($D$15:$D$20<>"")*($E$15:$E$20<>""))+SUMPRODUCT(($F$15:$F$20=$H18)*($D$15:$D$20<>"")*($E$15:$E$20<>"")) -> 3 | J18: =SUMPRODUCT(($C$15:$C$20=$H18)*($D$15:$D$20<>"")*($E$15:$E$20<>"")*($D$15:$D$20>$E$15:$E$20))*3+SUMPRODUCT(($F$15:$F$20=$H18)*($D$15:$D$20<>"")*($E$15:$E$20<>"")*($E$15:$E$20>$D$15:$D$20))*3+SUMPRODUCT((($C$15:$C$20=$H18)+($F$15:$F$20=$H18))*($D$15:$D$20<>"")*($E$15:$E$20<>"")*($D$15:$D$20=$E$15:$E$20)) -> 7 | K18: =SUMPRODUCT(($C$15:$C$20=$H18)*($D$15:$D$20<>"")*($E$15:$E$20<>"")*$D$15:$D$20)+SUMPRODUCT(($F$15:$F$20=$H18)*($D$15:$D$20<>"")*($E$15:$E$20<>"")*$E$15:$E$20) -> 3 | L18: =SUMPRODUCT(($C$15:$C$20=$H18)*($D$15:$D$20<>"")*($E$15:$E$20<>"")*$E$15:$E$20)+SUMPRODUCT(($F$15:$F$20=$H18)*($D$15:$D$20<>"")*($E$15:$E$20<>"")*$D$15:$D$20) -> 1 | M18: =K18-L18 -> 2 | N18: =J18*10000000+(M18+100)*10000+K18*10+(3-COUNTIF($H$15:$H$20,"<"&H18)) -> 71020030 | O18: =RANK(N18,$N$15:$N$20) -> 2
A19: 51 | B19: 2026-06-24 | C19: Suiza | D19: 1 | E19: 1 | F19: Canadá
A20: 52 | B20: 2026-06-24 | C20: Bosnia y Herzegovina | D20: 1 | E20: 1 | F20: Catar
A22: GRUPO C
A23: # | B23: Fecha | C23: Local | D23: GL | E23: GV | F23: Visitante | H23: Equipo | I23: PJ | J23: Pts | K23: GF | L23: GC | M23: Dif | N23: Score | O23: Pos
A24: 7 | B24: 2026-06-13 | C24: Brasil | D24: 1 | E24: 0 | F24: Marruecos | H24: Brasil | I24: =SUMPRODUCT(($C$24:$C$29=$H24)*($D$24:$D$29<>"")*($E$24:$E$29<>""))+SUMPRODUCT(($F$24:$F$29=$H24)*($D$24:$D$29<>"")*($E$24:$E$29<>"")) -> 3 | J24: =SUMPRODUCT(($C$24:$C$29=$H24)*($D$24:$D$29<>"")*($E$24:$E$29<>"")*($D$24:$D$29>$E$24:$E$29))*3+SUMPRODUCT(($F$24:$F$29=$H24)*($D$24:$D$29<>"")*($E$24:$E$29<>"")*($E$24:$E$29>$D$24:$D$29))*3+SUMPRODUCT((($C$24:$C$29=$H24)+($F$24:$F$29=$H24))*($D$24:$D$29<>"")*($E$24:$E$29<>"")*($D$24:$D$29=$E$24:$E$29)) -> 9 | K24: =SUMPRODUCT(($C$24:$C$29=$H24)*($D$24:$D$29<>"")*($E$24:$E$29<>"")*$D$24:$D$29)+SUMPRODUCT(($F$24:$F$29=$H24)*($D$24:$D$29<>"")*($E$24:$E$29<>"")*$E$24:$E$29) -> 5 | L24: =SUMPRODUCT(($C$24:$C$29=$H24)*($D$24:$D$29<>"")*($E$24:$E$29<>"")*$E$24:$E$29)+SUMPRODUCT(($F$24:$F$29=$H24)*($D$24:$D$29<>"")*($E$24:$E$29<>"")*$D$24:$D$29) -> 0 | M24: =K24-L24 -> 5 | N24: =J24*10000000+(M24+100)*10000+K24*10+(3-COUNTIF($H$24:$H$29,"<"&H24)) -> 91050053 | O24: =RANK(N24,$N$24:$N$29) -> 1 | Q24: 1°: | R24: =INDEX($H$24:$H$29,MATCH(1,$O$24:$O$29,0)) -> Brasil
A25: 8 | B25: 2026-06-13 | C25: Haití | D25: 0 | E25: 1 | F25: Escocia | H25: Marruecos | I25: =SUMPRODUCT(($C$24:$C$29=$H25)*($D$24:$D$29<>"")*($E$24:$E$29<>""))+SUMPRODUCT(($F$24:$F$29=$H25)*($D$24:$D$29<>"")*($E$24:$E$29<>"")) -> 3 | J25: =SUMPRODUCT(($C$24:$C$29=$H25)*($D$24:$D$29<>"")*($E$24:$E$29<>"")*($D$24:$D$29>$E$24:$E$29))*3+SUMPRODUCT(($F$24:$F$29=$H25)*($D$24:$D$29<>"")*($E$24:$E$29<>"")*($E$24:$E$29>$D$24:$D$29))*3+SUMPRODUCT((($C$24:$C$29=$H25)+($F$24:$F$29=$H25))*($D$24:$D$29<>"")*($E$24:$E$29<>"")*($D$24:$D$29=$E$24:$E$29)) -> 6 | K25: =SUMPRODUCT(($C$24:$C$29=$H25)*($D$24:$D$29<>"")*($E$24:$E$29<>"")*$D$24:$D$29)+SUMPRODUCT(($F$24:$F$29=$H25)*($D$24:$D$29<>"")*($E$24:$E$29<>"")*$E$24:$E$29) -> 3 | L25: =SUMPRODUCT(($C$24:$C$29=$H25)*($D$24:$D$29<>"")*($E$24:$E$29<>"")*$E$24:$E$29)+SUMPRODUCT(($F$24:$F$29=$H25)*($D$24:$D$29<>"")*($E$24:$E$29<>"")*$D$24:$D$29) -> 1 | M25: =K25-L25 -> 2 | N25: =J25*10000000+(M25+100)*10000+K25*10+(3-COUNTIF($H$24:$H$29,"<"&H25)) -> 61020030 | O25: =RANK(N25,$N$24:$N$29) -> 2 | Q25: 2°: | R25: =INDEX($H$24:$H$29,MATCH(2,$O$24:$O$29,0)) -> Marruecos
A26: 29 | B26: 2026-06-19 | C26: Escocia | D26: 0 | E26: 1 | F26: Marruecos | H26: Haití | I26: =SUMPRODUCT(($C$24:$C$29=$H26)*($D$24:$D$29<>"")*($E$24:$E$29<>""))+SUMPRODUCT(($F$24:$F$29=$H26)*($D$24:$D$29<>"")*($E$24:$E$29<>"")) -> 3 | J26: =SUMPRODUCT(($C$24:$C$29=$H26)*($D$24:$D$29<>"")*($E$24:$E$29<>"")*($D$24:$D$29>$E$24:$E$29))*3+SUMPRODUCT(($F$24:$F$29=$H26)*($D$24:$D$29<>"")*($E$24:$E$29<>"")*($E$24:$E$29>$D$24:$D$29))*3+SUMPRODUCT((($C$24:$C$29=$H26)+($F$24:$F$29=$H26))*($D$24:$D$29<>"")*($E$24:$E$29<>"")*($D$24:$D$29=$E$24:$E$29)) -> 0 | K26: =SUMPRODUCT(($C$24:$C$29=$H26)*($D$24:$D$29<>"")*($E$24:$E$29<>"")*$D$24:$D$29)+SUMPRODUCT(($F$24:$F$29=$H26)*($D$24:$D$29<>"")*($E$24:$E$29<>"")*$E$24:$E$29) -> 0 | L26: =SUMPRODUCT(($C$24:$C$29=$H26)*($D$24:$D$29<>"")*($E$24:$E$29<>"")*$E$24:$E$29)+SUMPRODUCT(($F$24:$F$29=$H26)*($D$24:$D$29<>"")*($E$24:$E$29<>"")*$D$24:$D$29) -> 5 | M26: =K26-L26 -> -5 | N26: =J26*10000000+(M26+100)*10000+K26*10+(3-COUNTIF($H$24:$H$29,"<"&H26)) -> 950001 | O26: =RANK(N26,$N$24:$N$29) -> 4 | Q26: 3°: | R26: =INDEX($H$24:$H$29,MATCH(3,$O$24:$O$29,0)) -> Escocia
A27: 30 | B27: 2026-06-19 | C27: Brasil | D27: 2 | E27: 0 | F27: Haití | H27: Escocia | I27: =SUMPRODUCT(($C$24:$C$29=$H27)*($D$24:$D$29<>"")*($E$24:$E$29<>""))+SUMPRODUCT(($F$24:$F$29=$H27)*($D$24:$D$29<>"")*($E$24:$E$29<>"")) -> 3 | J27: =SUMPRODUCT(($C$24:$C$29=$H27)*($D$24:$D$29<>"")*($E$24:$E$29<>"")*($D$24:$D$29>$E$24:$E$29))*3+SUMPRODUCT(($F$24:$F$29=$H27)*($D$24:$D$29<>"")*($E$24:$E$29<>"")*($E$24:$E$29>$D$24:$D$29))*3+SUMPRODUCT((($C$24:$C$29=$H27)+($F$24:$F$29=$H27))*($D$24:$D$29<>"")*($E$24:$E$29<>"")*($D$24:$D$29=$E$24:$E$29)) -> 3 | K27: =SUMPRODUCT(($C$24:$C$29=$H27)*($D$24:$D$29<>"")*($E$24:$E$29<>"")*$D$24:$D$29)+SUMPRODUCT(($F$24:$F$29=$H27)*($D$24:$D$29<>"")*($E$24:$E$29<>"")*$E$24:$E$29) -> 1 | L27: =SUMPRODUCT(($C$24:$C$29=$H27)*($D$24:$D$29<>"")*($E$24:$E$29<>"")*$E$24:$E$29)+SUMPRODUCT(($F$24:$F$29=$H27)*($D$24:$D$29<>"")*($E$24:$E$29<>"")*$D$24:$D$29) -> 3 | M27: =K27-L27 -> -2 | N27: =J27*10000000+(M27+100)*10000+K27*10+(3-COUNTIF($H$24:$H$29,"<"&H27)) -> 30980012 | O27: =RANK(N27,$N$24:$N$29) -> 3
A28: 53 | B28: 2026-06-24 | C28: Escocia | D28: 0 | E28: 2 | F28: Brasil
A29: 54 | B29: 2026-06-24 | C29: Marruecos | D29: 2 | E29: 0 | F29: Haití
A31: GRUPO D
A32: # | B32: Fecha | C32: Local | D32: GL | E32: GV | F32: Visitante | H32: Equipo | I32: PJ | J32: Pts | K32: GF | L32: GC | M32: Dif | N32: Score | O32: Pos
A33: 4 | B33: 2026-06-12 | C33: Estados Unidos | D33: 1 | E33: 0 | F33: Paraguay | H33: Estados Unidos | I33: =SUMPRODUCT(($C$33:$C$38=$H33)*($D$33:$D$38<>"")*($E$33:$E$38<>""))+SUMPRODUCT(($F$33:$F$38=$H33)*($D$33:$D$38<>"")*($E$33:$E$38<>"")) -> 3 | J33: =SUMPRODUCT(($C$33:$C$38=$H33)*($D$33:$D$38<>"")*($E$33:$E$38<>"")*($D$33:$D$38>$E$33:$E$38))*3+SUMPRODUCT(($F$33:$F$38=$H33)*($D$33:$D$38<>"")*($E$33:$E$38<>"")*($E$33:$E$38>$D$33:$D$38))*3+SUMPRODUCT((($C$33:$C$38=$H33)+($F$33:$F$38=$H33))*($D$33:$D$38<>"")*($E$33:$E$38<>"")*($D$33:$D$38=$E$33:$E$38)) -> 5 | K33: =SUMPRODUCT(($C$33:$C$38=$H33)*($D$33:$D$38<>"")*($E$33:$E$38<>"")*$D$33:$D$38)+SUMPRODUCT(($F$33:$F$38=$H33)*($D$33:$D$38<>"")*($E$33:$E$38<>"")*$E$33:$E$38) -> 3 | L33: =SUMPRODUCT(($C$33:$C$38=$H33)*($D$33:$D$38<>"")*($E$33:$E$38<>"")*$E$33:$E$38)+SUMPRODUCT(($F$33:$F$38=$H33)*($D$33:$D$38<>"")*($E$33:$E$38<>"")*$D$33:$D$38) -> 2 | M33: =K33-L33 -> 1 | N33: =J33*10000000+(M33+100)*10000+K33*10+(3-COUNTIF($H$33:$H$38,"<"&H33)) -> 51010032 | O33: =RANK(N33,$N$33:$N$38) -> 1 | Q33: 1°: | R33: =INDEX($H$33:$H$38,MATCH(1,$O$33:$O$38,0)) -> Estados Unidos
A34: 6 | B34: 2026-06-13 | C34: Australia | D34: 1 | E34: 1 | F34: Turquía | H34: Paraguay | I34: =SUMPRODUCT(($C$33:$C$38=$H34)*($D$33:$D$38<>"")*($E$33:$E$38<>""))+SUMPRODUCT(($F$33:$F$38=$H34)*($D$33:$D$38<>"")*($E$33:$E$38<>"")) -> 3 | J34: =SUMPRODUCT(($C$33:$C$38=$H34)*($D$33:$D$38<>"")*($E$33:$E$38<>"")*($D$33:$D$38>$E$33:$E$38))*3+SUMPRODUCT(($F$33:$F$38=$H34)*($D$33:$D$38<>"")*($E$33:$E$38<>"")*($E$33:$E$38>$D$33:$D$38))*3+SUMPRODUCT((($C$33:$C$38=$H34)+($F$33:$F$38=$H34))*($D$33:$D$38<>"")*($E$33:$E$38<>"")*($D$33:$D$38=$E$33:$E$38)) -> 2 | K34: =SUMPRODUCT(($C$33:$C$38=$H34)*($D$33:$D$38<>"")*($E$33:$E$38<>"")*$D$33:$D$38)+SUMPRODUCT(($F$33:$F$38=$H34)*($D$33:$D$38<>"")*($E$33:$E$38<>"")*$E$33:$E$38) -> 2 | L34: =SUMPRODUCT(($C$33:$C$38=$H34)*($D$33:$D$38<>"")*($E$33:$E$38<>"")*$E$33:$E$38)+SUMPRODUCT(($F$33:$F$38=$H34)*($D$33:$D$38<>"")*($E$33:$E$38<>"")*$D$33:$D$38) -> 3 | M34: =K34-L34 -> -1 | N34: =J34*10000000+(M34+100)*10000+K34*10+(3-COUNTIF($H$33:$H$38,"<"&H34)) -> 20990021 | O34: =RANK(N34,$N$33:$N$38) -> 4 | Q34: 2°: | R34: =INDEX($H$33:$H$38,MATCH(2,$O$33:$O$38,0)) -> Australia
A35: 31 | B35: 2026-06-19 | C35: Estados Unidos | D35: 1 | E35: 1 | F35: Australia | H35: Australia | I35: =SUMPRODUCT(($C$33:$C$38=$H35)*($D$33:$D$38<>"")*($E$33:$E$38<>""))+SUMPRODUCT(($F$33:$F$38=$H35)*($D$33:$D$38<>"")*($E$33:$E$38<>"")) -> 3 | J35: =SUMPRODUCT(($C$33:$C$38=$H35)*($D$33:$D$38<>"")*($E$33:$E$38<>"")*($D$33:$D$38>$E$33:$E$38))*3+SUMPRODUCT(($F$33:$F$38=$H35)*($D$33:$D$38<>"")*($E$33:$E$38<>"")*($E$33:$E$38>$D$33:$D$38))*3+SUMPRODUCT((($C$33:$C$38=$H35)+($F$33:$F$38=$H35))*($D$33:$D$38<>"")*($E$33:$E$38<>"")*($D$33:$D$38=$E$33:$E$38)) -> 3 | K35: =SUMPRODUCT(($C$33:$C$38=$H35)*($D$33:$D$38<>"")*($E$33:$E$38<>"")*$D$33:$D$38)+SUMPRODUCT(($F$33:$F$38=$H35)*($D$33:$D$38<>"")*($E$33:$E$38<>"")*$E$33:$E$38) -> 3 | L35: =SUMPRODUCT(($C$33:$C$38=$H35)*($D$33:$D$38<>"")*($E$33:$E$38<>"")*$E$33:$E$38)+SUMPRODUCT(($F$33:$F$38=$H35)*($D$33:$D$38<>"")*($E$33:$E$38<>"")*$D$33:$D$38) -> 3 | M35: =K35-L35 -> 0 | N35: =J35*10000000+(M35+100)*10000+K35*10+(3-COUNTIF($H$33:$H$38,"<"&H35)) -> 31000033 | O35: =RANK(N35,$N$33:$N$38) -> 2 | Q35: 3°: | R35: =INDEX($H$33:$H$38,MATCH(3,$O$33:$O$38,0)) -> Turquía
A36: 32 | B36: 2026-06-19 | C36: Turquía | D36: 1 | E36: 1 | F36: Paraguay | H36: Turquía | I36: =SUMPRODUCT(($C$33:$C$38=$H36)*($D$33:$D$38<>"")*($E$33:$E$38<>""))+SUMPRODUCT(($F$33:$F$38=$H36)*($D$33:$D$38<>"")*($E$33:$E$38<>"")) -> 3 | J36: =SUMPRODUCT(($C$33:$C$38=$H36)*($D$33:$D$38<>"")*($E$33:$E$38<>"")*($D$33:$D$38>$E$33:$E$38))*3+SUMPRODUCT(($F$33:$F$38=$H36)*($D$33:$D$38<>"")*($E$33:$E$38<>"")*($E$33:$E$38>$D$33:$D$38))*3+SUMPRODUCT((($C$33:$C$38=$H36)+($F$33:$F$38=$H36))*($D$33:$D$38<>"")*($E$33:$E$38<>"")*($D$33:$D$38=$E$33:$E$38)) -> 3 | K36: =SUMPRODUCT(($C$33:$C$38=$H36)*($D$33:$D$38<>"")*($E$33:$E$38<>"")*$D$33:$D$38)+SUMPRODUCT(($F$33:$F$38=$H36)*($D$33:$D$38<>"")*($E$33:$E$38<>"")*$E$33:$E$38) -> 3 | L36: =SUMPRODUCT(($C$33:$C$38=$H36)*($D$33:$D$38<>"")*($E$33:$E$38<>"")*$E$33:$E$38)+SUMPRODUCT(($F$33:$F$38=$H36)*($D$33:$D$38<>"")*($E$33:$E$38<>"")*$D$33:$D$38) -> 3 | M36: =K36-L36 -> 0 | N36: =J36*10000000+(M36+100)*10000+K36*10+(3-COUNTIF($H$33:$H$38,"<"&H36)) -> 31000030 | O36: =RANK(N36,$N$33:$N$38) -> 3
A37: 55 | B37: 2026-06-25 | C37: Turquía | D37: 1 | E37: 1 | F37: Estados Unidos
A38: 56 | B38: 2026-06-25 | C38: Paraguay | D38: 1 | E38: 1 | F38: Australia
A40: GRUPO E
A41: # | B41: Fecha | C41: Local | D41: GL | E41: GV | F41: Visitante | H41: Equipo | I41: PJ | J41: Pts | K41: GF | L41: GC | M41: Dif | N41: Score | O41: Pos
A42: 9 | B42: 2026-06-14 | C42: Alemania | D42: 2 | E42: 0 | F42: Curazao | H42: Alemania | I42: =SUMPRODUCT(($C$42:$C$47=$H42)*($D$42:$D$47<>"")*($E$42:$E$47<>""))+SUMPRODUCT(($F$42:$F$47=$H42)*($D$42:$D$47<>"")*($E$42:$E$47<>"")) -> 3 | J42: =SUMPRODUCT(($C$42:$C$47=$H42)*($D$42:$D$47<>"")*($E$42:$E$47<>"")*($D$42:$D$47>$E$42:$E$47))*3+SUMPRODUCT(($F$42:$F$47=$H42)*($D$42:$D$47<>"")*($E$42:$E$47<>"")*($E$42:$E$47>$D$42:$D$47))*3+SUMPRODUCT((($C$42:$C$47=$H42)+($F$42:$F$47=$H42))*($D$42:$D$47<>"")*($E$42:$E$47<>"")*($D$42:$D$47=$E$42:$E$47)) -> 7 | K42: =SUMPRODUCT(($C$42:$C$47=$H42)*($D$42:$D$47<>"")*($E$42:$E$47<>"")*$D$42:$D$47)+SUMPRODUCT(($F$42:$F$47=$H42)*($D$42:$D$47<>"")*($E$42:$E$47<>"")*$E$42:$E$47) -> 4 | L42: =SUMPRODUCT(($C$42:$C$47=$H42)*($D$42:$D$47<>"")*($E$42:$E$47<>"")*$E$42:$E$47)+SUMPRODUCT(($F$42:$F$47=$H42)*($D$42:$D$47<>"")*($E$42:$E$47<>"")*$D$42:$D$47) -> 1 | M42: =K42-L42 -> 3 | N42: =J42*10000000+(M42+100)*10000+K42*10+(3-COUNTIF($H$42:$H$47,"<"&H42)) -> 71030043 | O42: =RANK(N42,$N$42:$N$47) -> 1 | Q42: 1°: | R42: =INDEX($H$42:$H$47,MATCH(1,$O$42:$O$47,0)) -> Alemania
A43: 10 | B43: 2026-06-14 | C43: Costa de Marfil | D43: 0 | E43: 1 | F43: Ecuador | H43: Curazao | I43: =SUMPRODUCT(($C$42:$C$47=$H43)*($D$42:$D$47<>"")*($E$42:$E$47<>""))+SUMPRODUCT(($F$42:$F$47=$H43)*($D$42:$D$47<>"")*($E$42:$E$47<>"")) -> 3 | J43: =SUMPRODUCT(($C$42:$C$47=$H43)*($D$42:$D$47<>"")*($E$42:$E$47<>"")*($D$42:$D$47>$E$42:$E$47))*3+SUMPRODUCT(($F$42:$F$47=$H43)*($D$42:$D$47<>"")*($E$42:$E$47<>"")*($E$42:$E$47>$D$42:$D$47))*3+SUMPRODUCT((($C$42:$C$47=$H43)+($F$42:$F$47=$H43))*($D$42:$D$47<>"")*($E$42:$E$47<>"")*($D$42:$D$47=$E$42:$E$47)) -> 0 | K43: =SUMPRODUCT(($C$42:$C$47=$H43)*($D$42:$D$47<>"")*($E$42:$E$47<>"")*$D$42:$D$47)+SUMPRODUCT(($F$42:$F$47=$H43)*($D$42:$D$47<>"")*($E$42:$E$47<>"")*$E$42:$E$47) -> 0 | L43: =SUMPRODUCT(($C$42:$C$47=$H43)*($D$42:$D$47<>"")*($E$42:$E$47<>"")*$E$42:$E$47)+SUMPRODUCT(($F$42:$F$47=$H43)*($D$42:$D$47<>"")*($E$42:$E$47<>"")*$D$42:$D$47) -> 5 | M43: =K43-L43 -> -5 | N43: =J43*10000000+(M43+100)*10000+K43*10+(3-COUNTIF($H$42:$H$47,"<"&H43)) -> 950001 | O43: =RANK(N43,$N$42:$N$47) -> 4 | Q43: 2°: | R43: =INDEX($H$42:$H$47,MATCH(2,$O$42:$O$47,0)) -> Ecuador
A44: 33 | B44: 2026-06-20 | C44: Alemania | D44: 1 | E44: 0 | F44: Costa de Marfil | H44: Costa de Marfil | I44: =SUMPRODUCT(($C$42:$C$47=$H44)*($D$42:$D$47<>"")*($E$42:$E$47<>""))+SUMPRODUCT(($F$42:$F$47=$H44)*($D$42:$D$47<>"")*($E$42:$E$47<>"")) -> 3 | J44: =SUMPRODUCT(($C$42:$C$47=$H44)*($D$42:$D$47<>"")*($E$42:$E$47<>"")*($D$42:$D$47>$E$42:$E$47))*3+SUMPRODUCT(($F$42:$F$47=$H44)*($D$42:$D$47<>"")*($E$42:$E$47<>"")*($E$42:$E$47>$D$42:$D$47))*3+SUMPRODUCT((($C$42:$C$47=$H44)+($F$42:$F$47=$H44))*($D$42:$D$47<>"")*($E$42:$E$47<>"")*($D$42:$D$47=$E$42:$E$47)) -> 3 | K44: =SUMPRODUCT(($C$42:$C$47=$H44)*($D$42:$D$47<>"")*($E$42:$E$47<>"")*$D$42:$D$47)+SUMPRODUCT(($F$42:$F$47=$H44)*($D$42:$D$47<>"")*($E$42:$E$47<>"")*$E$42:$E$47) -> 1 | L44: =SUMPRODUCT(($C$42:$C$47=$H44)*($D$42:$D$47<>"")*($E$42:$E$47<>"")*$E$42:$E$47)+SUMPRODUCT(($F$42:$F$47=$H44)*($D$42:$D$47<>"")*($E$42:$E$47<>"")*$D$42:$D$47) -> 2 | M44: =K44-L44 -> -1 | N44: =J44*10000000+(M44+100)*10000+K44*10+(3-COUNTIF($H$42:$H$47,"<"&H44)) -> 30990012 | O44: =RANK(N44,$N$42:$N$47) -> 3 | Q44: 3°: | R44: =INDEX($H$42:$H$47,MATCH(3,$O$42:$O$47,0)) -> Costa de Marfil
A45: 34 | B45: 2026-06-20 | C45: Ecuador | D45: 2 | E45: 0 | F45: Curazao | H45: Ecuador | I45: =SUMPRODUCT(($C$42:$C$47=$H45)*($D$42:$D$47<>"")*($E$42:$E$47<>""))+SUMPRODUCT(($F$42:$F$47=$H45)*($D$42:$D$47<>"")*($E$42:$E$47<>"")) -> 3 | J45: =SUMPRODUCT(($C$42:$C$47=$H45)*($D$42:$D$47<>"")*($E$42:$E$47<>"")*($D$42:$D$47>$E$42:$E$47))*3+SUMPRODUCT(($F$42:$F$47=$H45)*($D$42:$D$47<>"")*($E$42:$E$47<>"")*($E$42:$E$47>$D$42:$D$47))*3+SUMPRODUCT((($C$42:$C$47=$H45)+($F$42:$F$47=$H45))*($D$42:$D$47<>"")*($E$42:$E$47<>"")*($D$42:$D$47=$E$42:$E$47)) -> 7 | K45: =SUMPRODUCT(($C$42:$C$47=$H45)*($D$42:$D$47<>"")*($E$42:$E$47<>"")*$D$42:$D$47)+SUMPRODUCT(($F$42:$F$47=$H45)*($D$42:$D$47<>"")*($E$42:$E$47<>"")*$E$42:$E$47) -> 4 | L45: =SUMPRODUCT(($C$42:$C$47=$H45)*($D$42:$D$47<>"")*($E$42:$E$47<>"")*$E$42:$E$47)+SUMPRODUCT(($F$42:$F$47=$H45)*($D$42:$D$47<>"")*($E$42:$E$47<>"")*$D$42:$D$47) -> 1 | M45: =K45-L45 -> 3 | N45: =J45*10000000+(M45+100)*10000+K45*10+(3-COUNTIF($H$42:$H$47,"<"&H45)) -> 71030040 | O45: =RANK(N45,$N$42:$N$47) -> 2
...

Sheet Terceros
A1: RANKING DE TERCEROS LUGARES (auto-calculado; los 8 primeros avanzan)
A3: Grupo | B3: Equipo | C3: Pts | D3: Dif | E3: GF | F3: Score | G3: Rank | H3: ¿Avanza?
A4: A | B4: =INDEX(Grupos!$H$6:$H$11,MATCH(3,Grupos!$O$6:$O$11,0)) -> Chequia | C4: =INDEX(Grupos!$J$6:$J$11,MATCH(3,Grupos!$O$6:$O$11,0)) -> 2 | D4: =INDEX(Grupos!$M$6:$M$11,MATCH(3,Grupos!$O$6:$O$11,0)) -> -2 | E4: =INDEX(Grupos!$K$6:$K$11,MATCH(3,Grupos!$O$6:$O$11,0)) -> 2 | F4: =C4*10000000+(D4+100)*10000+E4*10+(11-COUNTIF($B$4:$B$15,"<"&B4)) -> 20980028 | G4: =RANK(F4,$F$4:$F$15) -> 7 | H4: =IF(G4<=8,"SÍ","no") -> SÍ
A5: B | B5: =INDEX(Grupos!$H$15:$H$20,MATCH(3,Grupos!$O$15:$O$20,0)) -> Bosnia y Herzegovina | C5: =INDEX(Grupos!$J$15:$J$20,MATCH(3,Grupos!$O$15:$O$20,0)) -> 1 | D5: =INDEX(Grupos!$M$15:$M$20,MATCH(3,Grupos!$O$15:$O$20,0)) -> -2 | E5: =INDEX(Grupos!$K$15:$K$20,MATCH(3,Grupos!$O$15:$O$20,0)) -> 1 | F5: =C5*10000000+(D5+100)*10000+E5*10+(11-COUNTIF($B$4:$B$15,"<"&B5)) -> 10980019 | G5: =RANK(F5,$F$4:$F$15) -> 9 | H5: =IF(G5<=8,"SÍ","no") -> no
A6: C | B6: =INDEX(Grupos!$H$24:$H$29,MATCH(3,Grupos!$O$24:$O$29,0)) -> Escocia | C6: =INDEX(Grupos!$J$24:$J$29,MATCH(3,Grupos!$O$24:$O$29,0)) -> 3 | D6: =INDEX(Grupos!$M$24:$M$29,MATCH(3,Grupos!$O$24:$O$29,0)) -> -2 | E6: =INDEX(Grupos!$K$24:$K$29,MATCH(3,Grupos!$O$24:$O$29,0)) -> 1 | F6: =C6*10000000+(D6+100)*10000+E6*10+(11-COUNTIF($B$4:$B$15,"<"&B6)) -> 30980015 | G6: =RANK(F6,$F$4:$F$15) -> 5 | H6: =IF(G6<=8,"SÍ","no") -> SÍ
A7: D | B7: =INDEX(Grupos!$H$33:$H$38,MATCH(3,Grupos!$O$33:$O$38,0)) -> Turquía | C7: =INDEX(Grupos!$J$33:$J$38,MATCH(3,Grupos!$O$33:$O$38,0)) -> 3 | D7: =INDEX(Grupos!$M$33:$M$38,MATCH(3,Grupos!$O$33:$O$38,0)) -> 0 | E7: =INDEX(Grupos!$K$33:$K$38,MATCH(3,Grupos!$O$33:$O$38,0)) -> 3 | F7: =C7*10000000+(D7+100)*10000+E7*10+(11-COUNTIF($B$4:$B$15,"<"&B7)) -> 31000030 | G7: =RANK(F7,$F$4:$F$15) -> 3 | H7: =IF(G7<=8,"SÍ","no") -> SÍ
A8: E | B8: =INDEX(Grupos!$H$42:$H$47,MATCH(3,Grupos!$O$42:$O$47,0)) -> Costa de Marfil | C8: =INDEX(Grupos!$J$42:$J$47,MATCH(3,Grupos!$O$42:$O$47,0)) -> 3 | D8: =INDEX(Grupos!$M$42:$M$47,MATCH(3,Grupos!$O$42:$O$47,0)) -> -1 | E8: =INDEX(Grupos!$K$42:$K$47,MATCH(3,Grupos!$O$42:$O$47,0)) -> 1 | F8: =C8*10000000+(D8+100)*10000+E8*10+(11-COUNTIF($B$4:$B$15,"<"&B8)) -> 30990017 | G8: =RANK(F8,$F$4:$F$15) -> 4 | H8: =IF(G8<=8,"SÍ","no") -> SÍ
A9: F | B9: =INDEX(Grupos!$H$51:$H$56,MATCH(3,Grupos!$O$51:$O$56,0)) -> Suecia | C9: =INDEX(Grupos!$J$51:$J$56,MATCH(3,Grupos!$O$51:$O$56,0)) -> 2 | D9: =INDEX(Grupos!$M$51:$M$56,MATCH(3,Grupos!$O$51:$O$56,0)) -> -2 | E9: =INDEX(Grupos!$K$51:$K$56,MATCH(3,Grupos!$O$51:$O$56,0)) -> 2 | F9: =C9*10000000+(D9+100)*10000+E9*10+(11-COUNTIF($B$4:$B$15,"<"&B9)) -> 20980021 | G9: =RANK(F9,$F$4:$F$15) -> 8 | H9: =IF(G9<=8,"SÍ","no") -> SÍ
A10: G | B10: =INDEX(Grupos!$H$60:$H$65,MATCH(3,Grupos!$O$60:$O$65,0)) -> Egipto | C10: =INDEX(Grupos!$J$60:$J$65,MATCH(3,Grupos!$O$60:$O$65,0)) -> 5 | D10: =INDEX(Grupos!$M$60:$M$65,MATCH(3,Grupos!$O$60:$O$65,0)) -> 1 | E10: =INDEX(Grupos!$K$60:$K$65,MATCH(3,Grupos!$O$60:$O$65,0)) -> 3 | F10: =C10*10000000+(D10+100)*10000+E10*10+(11-COUNTIF($B$4:$B$15,"<"&B10)) -> 51010036 | G10: =RANK(F10,$F$4:$F$15) -> 1 | H10: =IF(G10<=8,"SÍ","no") -> SÍ
A11: H | B11: =INDEX(Grupos!$H$69:$H$74,MATCH(3,Grupos!$O$69:$O$74,0)) -> Arabia Saudita | C11: =INDEX(Grupos!$J$69:$J$74,MATCH(3,Grupos!$O$69:$O$74,0)) -> 1 | D11: =INDEX(Grupos!$M$69:$M$74,MATCH(3,Grupos!$O$69:$O$74,0)) -> -3 | E11: =INDEX(Grupos!$K$69:$K$74,MATCH(3,Grupos!$O$69:$O$74,0)) -> 1 | F11: =C11*10000000+(D11+100)*10000+E11*10+(11-COUNTIF($B$4:$B$15,"<"&B11)) -> 10970021 | G11: =RANK(F11,$F$4:$F$15) -> 10 | H11: =IF(G11<=8,"SÍ","no") -> no
A12: I | B12: =INDEX(Grupos!$H$78:$H$83,MATCH(3,Grupos!$O$78:$O$83,0)) -> Senegal | C12: =INDEX(Grupos!$J$78:$J$83,MATCH(3,Grupos!$O$78:$O$83,0)) -> 1 | D12: =INDEX(Grupos!$M$78:$M$83,MATCH(3,Grupos!$O$78:$O$83,0)) -> -3 | E12: =INDEX(Grupos!$K$78:$K$83,MATCH(3,Grupos!$O$78:$O$83,0)) -> 1 | F12: =C12*10000000+(D12+100)*10000+E12*10+(11-COUNTIF($B$4:$B$15,"<"&B12)) -> 10970012 | G12: =RANK(F12,$F$4:$F$15) -> 11 | H12: =IF(G12<=8,"SÍ","no") -> no
A13: J | B13: =INDEX(Grupos!$H$87:$H$92,MATCH(3,Grupos!$O$87:$O$92,0)) -> Austria | C13: =INDEX(Grupos!$J$87:$J$92,MATCH(3,Grupos!$O$87:$O$92,0)) -> 4 | D13: =INDEX(Grupos!$M$87:$M$92,MATCH(3,Grupos!$O$87:$O$92,0)) -> -1 | E13: =INDEX(Grupos!$K$87:$K$92,MATCH(3,Grupos!$O$87:$O$92,0)) -> 2 | F13: =C13*10000000+(D13+100)*10000+E13*10+(11-COUNTIF($B$4:$B$15,"<"&B13)) -> 40990030 | G13: =RANK(F13,$F$4:$F$15) -> 2 | H13: =IF(G13<=8,"SÍ","no") -> SÍ
A14: K | B14: =INDEX(Grupos!$H$96:$H$101,MATCH(3,Grupos!$O$96:$O$101,0)) -> RD Congo | C14: =INDEX(Grupos!$J$96:$J$101,MATCH(3,Grupos!$O$96:$O$101,0)) -> 1 | D14: =INDEX(Grupos!$M$96:$M$101,MATCH(3,Grupos!$O$96:$O$101,0)) -> -4 | E14: =INDEX(Grupos!$K$96:$K$101,MATCH(3,Grupos!$O$96:$O$101,0)) -> 1 | F14: =C14*10000000+(D14+100)*10000+E14*10+(11-COUNTIF($B$4:$B$15,"<"&B14)) -> 10960013 | G14: =RANK(F14,$F$4:$F$15) -> 12 | H14: =IF(G14<=8,"SÍ","no") -> no
A15: L | B15: =INDEX(Grupos!$H$105:$H$110,MATCH(3,Grupos!$O$105:$O$110,0)) -> Panamá | C15: =INDEX(Grupos!$J$105:$J$110,MATCH(3,Grupos!$O$105:$O$110,0)) -> 3 | D15: =INDEX(Grupos!$M$105:$M$110,MATCH(3,Grupos!$O$105:$O$110,0)) -> -2 | E15: =INDEX(Grupos!$K$105:$K$110,MATCH(3,Grupos!$O$105:$O$110,0)) -> 1 | F15: =C15*10000000+(D15+100)*10000+E15*10+(11-COUNTIF($B$4:$B$15,"<"&B15)) -> 30980014 | G15: =RANK(F15,$F$4:$F$15) -> 6 | H15: =IF(G15<=8,"SÍ","no") -> SÍ

Sheet Bracket
A1: ELIMINATORIA (partidos 73-104) — llena SOLO GL/GV; SIN empates (penales = +1 gol al ganador)
A2: Slots 1X/2X y ganadores W## por fórmula. Slots de terceros (3°): los escribe la simulación como VALOR (asignación FIFA aproximada por elegibilidad — ver data/bracket.json).
A4: # | B4: Ronda | C4: Fecha | D4: Ciudad | E4: Slot L | F4: Local | G4: GL | H4: GV | I4: Visitante | J4: Slot V
A5: 73 | B5: Dieciseisavos | C5: 2026-06-29 | D5: Los Ángeles | E5: 1J | F5: =Grupos!$R$87 -> Argentina | G5: 2 | H5: 0 | I5: =Grupos!$R$70 -> Uruguay | J5: 2H
A6: 74 | B6: Dieciseisavos | C6: 2026-07-03 | D6: Dallas | E6: 2D | F6: =Grupos!$R$34 -> Australia | G6: 1 | H6: 2 | I6: =Grupos!$R$61 -> Irán | J6: 2G
A7: 75 | B7: Dieciseisavos | C7: 2026-07-03 | D7: Filadelfia | E7: 1K | F7: =Grupos!$R$96 -> Portugal | G7: 2 | H7: 0 | I7: Panamá | J7: 3_DEIJL
A8: 76 | B8: Dieciseisavos | C8: 2026-07-02 | D8: Toronto | E8: 1G | F8: =Grupos!$R$60 -> Bélgica | G8: 2 | H8: 1 | I8: Chequia | J8: 3_AEHIJ
A9: 77 | B9: Dieciseisavos | C9: 2026-06-29 | D9: Houston | E9: 1C | F9: =Grupos!$R$24 -> Brasil | G9: 1 | H9: 0 | I9: =Grupos!$R$52 -> Japón | J9: 2F
A10: 78 | B10: Dieciseisavos | C10: 2026-06-30 | D10: San Francisco | E10: 2E | F10: =Grupos!$R$43 -> Ecuador | G10: 2 | H10: 1 | I10: =Grupos!$R$79 -> Noruega | J10: 2I
A11: 79 | B11: Dieciseisavos | C11: 2026-07-02 | D11: Boston | E11: 1L | F11: =Grupos!$R$105 -> Inglaterra | G11: 2 | H11: 0 | I11: Costa de Marfil | J11: 3_EHIJK
A12: 80 | B12: Dieciseisavos | C12: 2026-06-30 | D12: Ciudad de México | E12: 1A | F12: =Grupos!$R$6 -> México | G12: 2 | H12: 0 | I12: Escocia | J12: 3_CEFHI
A13: 81 | B13: Dieciseisavos | C13: 2026-07-02 | D13: Los Ángeles | E13: 1H | F13: =Grupos!$R$69 -> España | G13: 2 | H13: 0 | I13: =Grupos!$R$88 -> Argelia | J13: 2J
A14: 82 | B14: Dieciseisavos | C14: 2026-06-28 | D14: Los Ángeles | E14: 2A | F14: =Grupos!$R$7 -> Corea del Sur | G14: 1 | H14: 2 | I14: =Grupos!$R$16 -> Suiza | J14: 2B
A15: 83 | B15: Dieciseisavos | C15: 2026-06-29 | D15: Monterrey | E15: 1F | F15: =Grupos!$R$51 -> Holanda | G15: 2 | H15: 1 | I15: =Grupos!$R$25 -> Marruecos | J15: 2C
A16: 84 | B16: Dieciseisavos | C16: 2026-07-02 | D16: Vancouver | E16: 1B | F16: =Grupos!$R$15 -> Canadá | G16: 2 | H16: 1 | I16: Austria | J16: 3_EFGIJ
A17: 85 | B17: Dieciseisavos | C17: 2026-06-30 | D17: Nueva York | E17: 1I | F17: =Grupos!$R$78 -> Francia | G17: 2 | H17: 0 | I17: Egipto | J17: 3_CDFGH
A18: 86 | B18: Dieciseisavos | C18: 2026-07-01 | D18: Atlanta | E18: 2K | F18: =Grupos!$R$97 -> Colombia | G18: 2 | H18: 1 | I18: =Grupos!$R$106 -> Croacia | J18: 2L
A19: 87 | B19: Dieciseisavos | C19: 2026-07-01 | D19: Seattle | E19: 1E | F19: =Grupos!$R$42 -> Alemania | G19: 1 | H19: 0 | I19: Turquía | J19: 3_ABCDF
A20: 88 | B20: Dieciseisavos | C20: 2026-07-03 | D20: Kansas City | E20: 1D | F20: =Grupos!$R$33 -> Estados Unidos | G20: 1 | H20: 0 | I20: Suecia | J20: 3_BEFIJ
A21: 89 | B21: Octavos | C21: 2026-07-04 | D21: Houston | E21: W73 | F21: =IF(G5>H5,F5,I5) -> Argentina | G21: 2 | H21: 0 | I21: =IF(G6>H6,F6,I6) -> Irán | J21: W74
A22: 90 | B22: Octavos | C22: 2026-07-04 | D22: Filadelfia | E22: W75 | F22: =IF(G7>H7,F7,I7) -> Portugal | G22: 1 | H22: 0 | I22: =IF(G8>H8,F8,I8) -> Bélgica | J22: W76
A23: 91 | B23: Octavos | C23: 2026-07-05 | D23: Nueva York | E23: W77 | F23: =IF(G9>H9,F9,I9) -> Brasil | G23: 2 | H23: 1 | I23: =IF(G10>H10,F10,I10) -> Ecuador | J23: W78
A24: 92 | B24: Octavos | C24: 2026-07-05 | D24: Ciudad de México | E24: W79 | F24: =IF(G11>H11,F11,I11) -> Inglaterra | G24: 2 | H24: 1 | I24: =IF(G12>H12,F12,I12) -> México | J24: W80
A25: 93 | B25: Octavos | C25: 2026-07-06 | D25: Dallas | E25: W81 | F25: =IF(G13>H13,F13,I13) -> España | G25: 2 | H25: 0 | I25: =IF(G14>H14,F14,I14) -> Suiza | J25: W82
A26: 94 | B26: Octavos | C26: 2026-07-06 | D26: Seattle | E26: W83 | F26: =IF(G15>H15,F15,I15) -> Holanda | G26: 1 | H26: 0 | I26: =IF(G16>H16,F16,I16) -> Canadá | J26: W84
A27: 95 | B27: Octavos | C27: 2026-07-07 | D27: Atlanta | E27: W85 | F27: =IF(G17>H17,F17,I17) -> Francia | G27: 2 | H27: 1 | I27: =IF(G18>H18,F18,I18) -> Colombia | J27: W86
A28: 96 | B28: Octavos | C28: 2026-07-07 | D28: Vancouver | E28: W87 | F28: =IF(G19>H19,F19,I19) -> Alemania | G28: 2 | H28: 1 | I28: =IF(G20>H20,F20,I20) -> Estados Unidos | J28: W88
A29: 97 | B29: Cuartos | C29: 2026-07-11 | D29: Kansas City | E29: W89 | F29: =IF(G21>H21,F21,I21) -> Argentina | G29: 2 | H29: 1 | I29: =IF(G22>H22,F22,I22) -> Portugal | J29: W90
A30: 98 | B30: Cuartos | C30: 2026-07-11 | D30: Miami | E30: W91 | F30: =IF(G23>H23,F23,I23) -> Brasil | G30: 1 | H30: 2 | I30: =IF(G24>H24,F24,I24) -> Inglaterra | J30: W92
A31: 99 | B31: Cuartos | C31: 2026-07-09 | D31: Boston | E31: W93 | F31: =IF(G25>H25,F25,I25) -> España | G31: 1 | H31: 0 | I31: =IF(G26>H26,F26,I26) -> Holanda | J31: W94
A32: 100 | B32: Cuartos | C32: 2026-07-10 | D32: Los Ángeles | E32: W95 | F32: =IF(G27>H27,F27,I27) -> Francia | G32: 2 | H32: 1 | I32: =IF(G28>H28,F28,I28) -> Alemania | J32: W96
A33: 101 | B33: Semifinal | C33: 2026-07-15 | D33: Atlanta | E33: W97 | F33: =IF(G29>H29,F29,I29) -> Argentina | G33: 2 | H33: 1 | I33: =IF(G30>H30,F30,I30) -> Inglaterra | J33: W98
A34: 102 | B34: Semifinal | C34: 2026-07-14 | D34: Dallas | E34: W99 | F34: =IF(G31>H31,F31,I31) -> España | G34: 2 | H34: 1 | I34: =IF(G32>H32,F32,I32) -> Francia | J34: W100
A35: 103 | B35: 3er lugar | C35: 2026-07-18 | D35: Miami | E35: L101 | F35: =IF(G33>H33,I33,F33) -> Inglaterra | G35: 1 | H35: 2 | I35: =IF(G34>H34,I34,F34) -> Francia | J35: L102
A36: 104 | B36: FINAL | C36: 2026-07-19 | D36: Nueva York | E36: W101 | F36: =IF(G33>H33,F33,I33) -> Argentina | G36: 1 | H36: 2 | I36: =IF(G34>H34,F34,I34) -> España | J36: W102
A38: CAMPEÓN: | B38: =IF(G36>H36,F36,I36) -> España

Sheet Extras
A1: PREGUNTAS EXTRA (25 pts c/u)
A3: Bota de Oro (máximo goleador): | B3: Kylian Mbappé
A4: Último lugar del torneo: | B4: Curazao
A6: DATOS DEL PARTICIPANTE (dejar en blanco)
A7: Nombre:
A8: Email:
A9: Teléfono:
